ERROR 2015-11-24 16:58:54,041 base Internal Server Error: /es/dashboard/catalogue/products/208/delete/
Traceback (most recent call last):
  File "/usr/local/lib/python2.7/dist-packages/django/core/handlers/base.py", line 132, in get_response
    response = wrapped_callback(request, *callback_args, **callback_kwargs)
  File "/usr/local/lib/python2.7/dist-packages/django/utils/decorators.py", line 145, in inner
    return func(*args, **kwargs)
  File "/usr/local/lib/python2.7/dist-packages/django/db/transaction.py", line 232, in __exit__
    connection.commit()
  File "/usr/local/lib/python2.7/dist-packages/django/db/backends/base/base.py", line 173, in commit
    self._commit()
  File "/usr/local/lib/python2.7/dist-packages/django/db/backends/base/base.py", line 142, in _commit
    return self.connection.commit()
  File "/usr/local/lib/python2.7/dist-packages/django/db/utils.py", line 97, in __exit__
    six.reraise(dj_exc_type, dj_exc_value, traceback)
  File "/usr/local/lib/python2.7/dist-packages/django/db/backends/base/base.py", line 142, in _commit
    return self.connection.commit()
OperationalError: database is locked
ERROR 2015-11-24 16:59:36,189 base Internal Server Error: /es/dashboard/catalogue/products/201/delete/
Traceback (most recent call last):
  File "/usr/local/lib/python2.7/dist-packages/django/core/handlers/base.py", line 132, in get_response
    response = wrapped_callback(request, *callback_args, **callback_kwargs)
  File "/usr/local/lib/python2.7/dist-packages/django/utils/decorators.py", line 145, in inner
    return func(*args, **kwargs)
  File "/usr/local/lib/python2.7/dist-packages/django/db/transaction.py", line 232, in __exit__
    connection.commit()
  File "/usr/local/lib/python2.7/dist-packages/django/db/backends/base/base.py", line 173, in commit
    self._commit()
  File "/usr/local/lib/python2.7/dist-packages/django/db/backends/base/base.py", line 142, in _commit
    return self.connection.commit()
  File "/usr/local/lib/python2.7/dist-packages/django/db/utils.py", line 97, in __exit__
    six.reraise(dj_exc_type, dj_exc_value, traceback)
  File "/usr/local/lib/python2.7/dist-packages/django/db/backends/base/base.py", line 142, in _commit
    return self.connection.commit()
OperationalError: database is locked
